Traceback (most recent call last):
  File "sha256app.py", line 15, in <module>
  File "mainform.pyc", line 87, in __init__
  File "json\__init__.pyc", line 290, in load
  File "json\__init__.pyc", line 338, in loads
  File "json\decoder.pyc", line 366, in decode
  File "json\decoder.pyc", line 384, in raw_decode
ValueError: No JSON object could be decoded
Traceback (most recent call last):
  File "sha256app.py", line 15, in <module>
  File "mainform.pyc", line 87, in __init__
  File "json\__init__.pyc", line 290, in load
  File "json\__init__.pyc", line 338, in loads
  File "json\decoder.pyc", line 366, in decode
  File "json\decoder.pyc", line 384, in raw_decode
ValueError: No JSON object could be decoded
Traceback (most recent call last):
  File "sha256app.py", line 15, in <module>
  File "mainform.pyc", line 87, in __init__
  File "json\__init__.pyc", line 290, in load
  File "json\__init__.pyc", line 338, in loads
  File "json\decoder.pyc", line 366, in decode
  File "json\decoder.pyc", line 384, in raw_decode
ValueError: No JSON object could be decoded
